Traceback (most recent call last):
  File "/gpfs_backup/tuck_data/atan2/framed-with-fountain/dnastorage/system/pipeline_dnafile.py", line 51, in open
    raise Exception("store_header was false, trying file right away")
Exception: store_header was false, trying file right away
Traceback (most recent call last):
  File "/gpfs_backup/tuck_data/atan2/framed-with-fountain/dnastorage/system/pipeline_dnafile.py", line 51, in open
    raise Exception("store_header was false, trying file right away")
Exception: store_header was false, trying file right away
Traceback (most recent call last):
  File "/gpfs_backup/tuck_data/atan2/framed-with-fountain/dnastorage/system/pipeline_dnafile.py", line 51, in open
    raise Exception("store_header was false, trying file right away")
Exception: store_header was false, trying file right away
Traceback (most recent call last):
  File "/gpfs_backup/tuck_data/atan2/framed-with-fountain/dnastorage/system/pipeline_dnafile.py", line 51, in open
    raise Exception("store_header was false, trying file right away")
Exception: store_header was false, trying file right away
Traceback (most recent call last):
  File "/gpfs_backup/tuck_data/atan2/framed-with-fountain/dnastorage/system/pipeline_dnafile.py", line 51, in open
    raise Exception("store_header was false, trying file right away")
Exception: store_header was false, trying file right away
Traceback (most recent call last):
  File "/gpfs_backup/tuck_data/atan2/framed-with-fountain/dnastorage/system/pipeline_dnafile.py", line 51, in open
    raise Exception("store_header was false, trying file right away")
Exception: store_header was false, trying file right away
Traceback (most recent call last):
  File "/gpfs_backup/tuck_data/atan2/framed-with-fountain/dnastorage/system/pipeline_dnafile.py", line 51, in open
    raise Exception("store_header was false, trying file right away")
Exception: store_header was false, trying file right away
Traceback (most recent call last):
  File "/gpfs_backup/tuck_data/atan2/framed-with-fountain/dnastorage/system/pipeline_dnafile.py", line 51, in open
    raise Exception("store_header was false, trying file right away")
Exception: store_header was false, trying file right away
Traceback (most recent call last):
  File "/gpfs_backup/tuck_data/atan2/framed-with-fountain/dnastorage/system/pipeline_dnafile.py", line 51, in open
    raise Exception("store_header was false, trying file right away")
Exception: store_header was false, trying file right away
Traceback (most recent call last):
  File "/gpfs_backup/tuck_data/atan2/framed-with-fountain/dnastorage/system/pipeline_dnafile.py", line 51, in open
    raise Exception("store_header was false, trying file right away")
Exception: store_header was false, trying file right away
Traceback (most recent call last):
  File "/gpfs_backup/tuck_data/atan2/framed-with-fountain/dnastorage/system/pipeline_dnafile.py", line 51, in open
    raise Exception("store_header was false, trying file right away")
Exception: store_header was false, trying file right away
Traceback (most recent call last):
  File "/gpfs_backup/tuck_data/atan2/framed-with-fountain/dnastorage/system/pipeline_dnafile.py", line 51, in open
    raise Exception("store_header was false, trying file right away")
Exception: store_header was false, trying file right away
Traceback (most recent call last):
  File "/gpfs_backup/tuck_data/atan2/framed-with-fountain/dnastorage/system/pipeline_dnafile.py", line 51, in open
    raise Exception("store_header was false, trying file right away")
Exception: store_header was false, trying file right away
Traceback (most recent call last):
  File "/gpfs_backup/tuck_data/atan2/framed-with-fountain/dnastorage/system/pipeline_dnafile.py", line 51, in open
    raise Exception("store_header was false, trying file right away")
Exception: store_header was false, trying file right away
Traceback (most recent call last):
  File "/gpfs_backup/tuck_data/atan2/framed-with-fountain/dnastorage/system/pipeline_dnafile.py", line 51, in open
    raise Exception("store_header was false, trying file right away")
Exception: store_header was false, trying file right away
Traceback (most recent call last):
  File "/gpfs_backup/tuck_data/atan2/framed-with-fountain/dnastorage/system/pipeline_dnafile.py", line 51, in open
    raise Exception("store_header was false, trying file right away")
Exception: store_header was false, trying file right away
Traceback (most recent call last):
  File "/gpfs_backup/tuck_data/atan2/framed-with-fountain/dnastorage/system/pipeline_dnafile.py", line 51, in open
    raise Exception("store_header was false, trying file right away")
Exception: store_header was false, trying file right away
Traceback (most recent call last):
  File "/gpfs_backup/tuck_data/atan2/framed-with-fountain/dnastorage/system/pipeline_dnafile.py", line 51, in open
    raise Exception("store_header was false, trying file right away")
Exception: store_header was false, trying file right away
Traceback (most recent call last):
  File "/gpfs_backup/tuck_data/atan2/framed-with-fountain/dnastorage/system/pipeline_dnafile.py", line 51, in open
    raise Exception("store_header was false, trying file right away")
Exception: store_header was false, trying file right away
Traceback (most recent call last):
  File "/gpfs_backup/tuck_data/atan2/framed-with-fountain/dnastorage/system/pipeline_dnafile.py", line 51, in open
    raise Exception("store_header was false, trying file right away")
Exception: store_header was false, trying file right away
Traceback (most recent call last):
  File "/gpfs_backup/tuck_data/atan2/framed-with-fountain/dnastorage/system/pipeline_dnafile.py", line 51, in open
    raise Exception("store_header was false, trying file right away")
Exception: store_header was false, trying file right away
Traceback (most recent call last):
  File "/gpfs_backup/tuck_data/atan2/framed-with-fountain/dnastorage/system/pipeline_dnafile.py", line 51, in open
    raise Exception("store_header was false, trying file right away")
Exception: store_header was false, trying file right away
Traceback (most recent call last):
  File "/gpfs_backup/tuck_data/atan2/framed-with-fountain/dnastorage/system/pipeline_dnafile.py", line 51, in open
    raise Exception("store_header was false, trying file right away")
Exception: store_header was false, trying file right away
Traceback (most recent call last):
  File "/gpfs_backup/tuck_data/atan2/framed-with-fountain/dnastorage/system/pipeline_dnafile.py", line 51, in open
    raise Exception("store_header was false, trying file right away")
Exception: store_header was false, trying file right away
Traceback (most recent call last):
  File "/gpfs_backup/tuck_data/atan2/framed-with-fountain/dnastorage/system/pipeline_dnafile.py", line 51, in open
    raise Exception("store_header was false, trying file right away")
Exception: store_header was false, trying file right away
Traceback (most recent call last):
  File "/gpfs_backup/tuck_data/atan2/framed-with-fountain/dnastorage/system/pipeline_dnafile.py", line 51, in open
    raise Exception("store_header was false, trying file right away")
Exception: store_header was false, trying file right away
Traceback (most recent call last):
  File "/gpfs_backup/tuck_data/atan2/framed-with-fountain/dnastorage/system/pipeline_dnafile.py", line 51, in open
    raise Exception("store_header was false, trying file right away")
Exception: store_header was false, trying file right away
Traceback (most recent call last):
  File "/gpfs_backup/tuck_data/atan2/framed-with-fountain/dnastorage/system/pipeline_dnafile.py", line 51, in open
    raise Exception("store_header was false, trying file right away")
Exception: store_header was false, trying file right away
Traceback (most recent call last):
  File "/gpfs_backup/tuck_data/atan2/framed-with-fountain/dnastorage/system/pipeline_dnafile.py", line 51, in open
    raise Exception("store_header was false, trying file right away")
Exception: store_header was false, trying file right away
Traceback (most recent call last):
  File "/gpfs_backup/tuck_data/atan2/framed-with-fountain/dnastorage/system/pipeline_dnafile.py", line 51, in open
    raise Exception("store_header was false, trying file right away")
Exception: store_header was false, trying file right away
Traceback (most recent call last):
  File "/gpfs_backup/tuck_data/atan2/framed-with-fountain/dnastorage/system/pipeline_dnafile.py", line 51, in open
    raise Exception("store_header was false, trying file right away")
Exception: store_header was false, trying file right away
Traceback (most recent call last):
  File "/gpfs_backup/tuck_data/atan2/framed-with-fountain/dnastorage/system/pipeline_dnafile.py", line 51, in open
    raise Exception("store_header was false, trying file right away")
Exception: store_header was false, trying file right away
Traceback (most recent call last):
  File "/gpfs_backup/tuck_data/atan2/framed-with-fountain/dnastorage/system/pipeline_dnafile.py", line 51, in open
    raise Exception("store_header was false, trying file right away")
Exception: store_header was false, trying file right away
Traceback (most recent call last):
  File "/gpfs_backup/tuck_data/atan2/framed-with-fountain/dnastorage/system/pipeline_dnafile.py", line 51, in open
    raise Exception("store_header was false, trying file right away")
Exception: store_header was false, trying file right away
Traceback (most recent call last):
  File "/gpfs_backup/tuck_data/atan2/framed-with-fountain/dnastorage/system/pipeline_dnafile.py", line 51, in open
    raise Exception("store_header was false, trying file right away")
Exception: store_header was false, trying file right away
Traceback (most recent call last):
  File "/gpfs_backup/tuck_data/atan2/framed-with-fountain/dnastorage/system/pipeline_dnafile.py", line 51, in open
    raise Exception("store_header was false, trying file right away")
Exception: store_header was false, trying file right away
Traceback (most recent call last):
  File "/gpfs_backup/tuck_data/atan2/framed-with-fountain/dnastorage/system/pipeline_dnafile.py", line 51, in open
    raise Exception("store_header was false, trying file right away")
Exception: store_header was false, trying file right away
Traceback (most recent call last):
  File "/gpfs_backup/tuck_data/atan2/framed-with-fountain/dnastorage/system/pipeline_dnafile.py", line 51, in open
    raise Exception("store_header was false, trying file right away")
Exception: store_header was false, trying file right away
Traceback (most recent call last):
  File "/gpfs_backup/tuck_data/atan2/framed-with-fountain/dnastorage/system/pipeline_dnafile.py", line 51, in open
    raise Exception("store_header was false, trying file right away")
Exception: store_header was false, trying file right away
Traceback (most recent call last):
  File "/gpfs_backup/tuck_data/atan2/framed-with-fountain/dnastorage/system/pipeline_dnafile.py", line 51, in open
    raise Exception("store_header was false, trying file right away")
Exception: store_header was false, trying file right away
Traceback (most recent call last):
  File "/gpfs_backup/tuck_data/atan2/framed-with-fountain/dnastorage/system/pipeline_dnafile.py", line 51, in open
    raise Exception("store_header was false, trying file right away")
Exception: store_header was false, trying file right away
Traceback (most recent call last):
  File "/gpfs_backup/tuck_data/atan2/framed-with-fountain/dnastorage/system/pipeline_dnafile.py", line 51, in open
    raise Exception("store_header was false, trying file right away")
Exception: store_header was false, trying file right away
Traceback (most recent call last):
  File "/gpfs_backup/tuck_data/atan2/framed-with-fountain/dnastorage/system/pipeline_dnafile.py", line 51, in open
    raise Exception("store_header was false, trying file right away")
Exception: store_header was false, trying file right away
Traceback (most recent call last):
  File "/gpfs_backup/tuck_data/atan2/framed-with-fountain/dnastorage/system/pipeline_dnafile.py", line 51, in open
    raise Exception("store_header was false, trying file right away")
Exception: store_header was false, trying file right away
Traceback (most recent call last):
  File "/gpfs_backup/tuck_data/atan2/framed-with-fountain/dnastorage/system/pipeline_dnafile.py", line 51, in open
    raise Exception("store_header was false, trying file right away")
Exception: store_header was false, trying file right away
Traceback (most recent call last):
  File "/gpfs_backup/tuck_data/atan2/framed-with-fountain/dnastorage/system/pipeline_dnafile.py", line 51, in open
    raise Exception("store_header was false, trying file right away")
Exception: store_header was false, trying file right away
Traceback (most recent call last):
  File "/gpfs_backup/tuck_data/atan2/framed-with-fountain/dnastorage/system/pipeline_dnafile.py", line 51, in open
    raise Exception("store_header was false, trying file right away")
Exception: store_header was false, trying file right away
Traceback (most recent call last):
  File "/gpfs_backup/tuck_data/atan2/framed-with-fountain/dnastorage/system/pipeline_dnafile.py", line 51, in open
    raise Exception("store_header was false, trying file right away")
Exception: store_header was false, trying file right away
Traceback (most recent call last):
  File "/gpfs_backup/tuck_data/atan2/framed-with-fountain/dnastorage/system/pipeline_dnafile.py", line 51, in open
    raise Exception("store_header was false, trying file right away")
Exception: store_header was false, trying file right away
Traceback (most recent call last):
  File "/gpfs_backup/tuck_data/atan2/framed-with-fountain/dnastorage/system/pipeline_dnafile.py", line 51, in open
    raise Exception("store_header was false, trying file right away")
Exception: store_header was false, trying file right away
Traceback (most recent call last):
  File "/gpfs_backup/tuck_data/atan2/framed-with-fountain/dnastorage/system/pipeline_dnafile.py", line 51, in open
    raise Exception("store_header was false, trying file right away")
Exception: store_header was false, trying file right away
Traceback (most recent call last):
  File "/gpfs_backup/tuck_data/atan2/framed-with-fountain/dnastorage/system/pipeline_dnafile.py", line 51, in open
    raise Exception("store_header was false, trying file right away")
Exception: store_header was false, trying file right away
Traceback (most recent call last):
  File "/gpfs_backup/tuck_data/atan2/framed-with-fountain/dnastorage/system/pipeline_dnafile.py", line 51, in open
    raise Exception("store_header was false, trying file right away")
Exception: store_header was false, trying file right away
Traceback (most recent call last):
  File "/gpfs_backup/tuck_data/atan2/framed-with-fountain/dnastorage/system/pipeline_dnafile.py", line 51, in open
    raise Exception("store_header was false, trying file right away")
Exception: store_header was false, trying file right away
Traceback (most recent call last):
  File "/gpfs_backup/tuck_data/atan2/framed-with-fountain/dnastorage/system/pipeline_dnafile.py", line 51, in open
    raise Exception("store_header was false, trying file right away")
Exception: store_header was false, trying file right away
Traceback (most recent call last):
  File "/gpfs_backup/tuck_data/atan2/framed-with-fountain/dnastorage/system/pipeline_dnafile.py", line 51, in open
    raise Exception("store_header was false, trying file right away")
Exception: store_header was false, trying file right away
Traceback (most recent call last):
  File "/gpfs_backup/tuck_data/atan2/framed-with-fountain/dnastorage/system/pipeline_dnafile.py", line 51, in open
    raise Exception("store_header was false, trying file right away")
Exception: store_header was false, trying file right away
Traceback (most recent call last):
  File "/gpfs_backup/tuck_data/atan2/framed-with-fountain/dnastorage/system/pipeline_dnafile.py", line 51, in open
    raise Exception("store_header was false, trying file right away")
Exception: store_header was false, trying file right away
Traceback (most recent call last):
  File "/gpfs_backup/tuck_data/atan2/framed-with-fountain/dnastorage/system/pipeline_dnafile.py", line 51, in open
    raise Exception("store_header was false, trying file right away")
Exception: store_header was false, trying file right away
Traceback (most recent call last):
  File "/gpfs_backup/tuck_data/atan2/framed-with-fountain/dnastorage/system/pipeline_dnafile.py", line 51, in open
    raise Exception("store_header was false, trying file right away")
Exception: store_header was false, trying file right away
Traceback (most recent call last):
  File "/gpfs_backup/tuck_data/atan2/framed-with-fountain/dnastorage/system/pipeline_dnafile.py", line 51, in open
    raise Exception("store_header was false, trying file right away")
Exception: store_header was false, trying file right away
Traceback (most recent call last):
  File "/gpfs_backup/tuck_data/atan2/framed-with-fountain/dnastorage/system/pipeline_dnafile.py", line 51, in open
    raise Exception("store_header was false, trying file right away")
Exception: store_header was false, trying file right away
Traceback (most recent call last):
  File "/gpfs_backup/tuck_data/atan2/framed-with-fountain/dnastorage/system/pipeline_dnafile.py", line 51, in open
    raise Exception("store_header was false, trying file right away")
Exception: store_header was false, trying file right away
Traceback (most recent call last):
  File "/gpfs_backup/tuck_data/atan2/framed-with-fountain/dnastorage/system/pipeline_dnafile.py", line 51, in open
    raise Exception("store_header was false, trying file right away")
Exception: store_header was false, trying file right away
Traceback (most recent call last):
  File "/gpfs_backup/tuck_data/atan2/framed-with-fountain/dnastorage/system/pipeline_dnafile.py", line 51, in open
    raise Exception("store_header was false, trying file right away")
Exception: store_header was false, trying file right away
Traceback (most recent call last):
  File "/gpfs_backup/tuck_data/atan2/framed-with-fountain/dnastorage/system/pipeline_dnafile.py", line 51, in open
    raise Exception("store_header was false, trying file right away")
Exception: store_header was false, trying file right away
Traceback (most recent call last):
  File "/gpfs_backup/tuck_data/atan2/framed-with-fountain/dnastorage/system/pipeline_dnafile.py", line 51, in open
    raise Exception("store_header was false, trying file right away")
Exception: store_header was false, trying file right away
Traceback (most recent call last):
  File "/gpfs_backup/tuck_data/atan2/framed-with-fountain/dnastorage/system/pipeline_dnafile.py", line 51, in open
    raise Exception("store_header was false, trying file right away")
Exception: store_header was false, trying file right away
Traceback (most recent call last):
  File "/gpfs_backup/tuck_data/atan2/framed-with-fountain/dnastorage/system/pipeline_dnafile.py", line 51, in open
    raise Exception("store_header was false, trying file right away")
Exception: store_header was false, trying file right away
Traceback (most recent call last):
  File "/gpfs_backup/tuck_data/atan2/framed-with-fountain/dnastorage/system/pipeline_dnafile.py", line 51, in open
    raise Exception("store_header was false, trying file right away")
Exception: store_header was false, trying file right away
Traceback (most recent call last):
  File "/gpfs_backup/tuck_data/atan2/framed-with-fountain/dnastorage/system/pipeline_dnafile.py", line 51, in open
    raise Exception("store_header was false, trying file right away")
Exception: store_header was false, trying file right away
Traceback (most recent call last):
  File "/gpfs_backup/tuck_data/atan2/framed-with-fountain/dnastorage/system/pipeline_dnafile.py", line 51, in open
    raise Exception("store_header was false, trying file right away")
Exception: store_header was false, trying file right away
Traceback (most recent call last):
  File "/gpfs_backup/tuck_data/atan2/framed-with-fountain/dnastorage/system/pipeline_dnafile.py", line 51, in open
    raise Exception("store_header was false, trying file right away")
Exception: store_header was false, trying file right away
Traceback (most recent call last):
  File "/gpfs_backup/tuck_data/atan2/framed-with-fountain/dnastorage/system/pipeline_dnafile.py", line 51, in open
    raise Exception("store_header was false, trying file right away")
Exception: store_header was false, trying file right away
Traceback (most recent call last):
  File "/gpfs_backup/tuck_data/atan2/framed-with-fountain/dnastorage/system/pipeline_dnafile.py", line 51, in open
    raise Exception("store_header was false, trying file right away")
Exception: store_header was false, trying file right away
Traceback (most recent call last):
  File "/gpfs_backup/tuck_data/atan2/framed-with-fountain/dnastorage/system/pipeline_dnafile.py", line 51, in open
    raise Exception("store_header was false, trying file right away")
Exception: store_header was false, trying file right away
Traceback (most recent call last):
  File "/gpfs_backup/tuck_data/atan2/framed-with-fountain/dnastorage/system/pipeline_dnafile.py", line 51, in open
    raise Exception("store_header was false, trying file right away")
Exception: store_header was false, trying file right away
Traceback (most recent call last):
  File "/gpfs_backup/tuck_data/atan2/framed-with-fountain/dnastorage/system/pipeline_dnafile.py", line 51, in open
    raise Exception("store_header was false, trying file right away")
Exception: store_header was false, trying file right away
Traceback (most recent call last):
  File "/gpfs_backup/tuck_data/atan2/framed-with-fountain/dnastorage/system/pipeline_dnafile.py", line 51, in open
    raise Exception("store_header was false, trying file right away")
Exception: store_header was false, trying file right away
Traceback (most recent call last):
  File "/gpfs_backup/tuck_data/atan2/framed-with-fountain/dnastorage/system/pipeline_dnafile.py", line 51, in open
    raise Exception("store_header was false, trying file right away")
Exception: store_header was false, trying file right away
Traceback (most recent call last):
  File "/gpfs_backup/tuck_data/atan2/framed-with-fountain/dnastorage/system/pipeline_dnafile.py", line 51, in open
    raise Exception("store_header was false, trying file right away")
Exception: store_header was false, trying file right away
Traceback (most recent call last):
  File "/gpfs_backup/tuck_data/atan2/framed-with-fountain/dnastorage/system/pipeline_dnafile.py", line 51, in open
    raise Exception("store_header was false, trying file right away")
Exception: store_header was false, trying file right away
Traceback (most recent call last):
  File "/gpfs_backup/tuck_data/atan2/framed-with-fountain/dnastorage/system/pipeline_dnafile.py", line 51, in open
    raise Exception("store_header was false, trying file right away")
Exception: store_header was false, trying file right away
Traceback (most recent call last):
  File "/gpfs_backup/tuck_data/atan2/framed-with-fountain/dnastorage/system/pipeline_dnafile.py", line 51, in open
    raise Exception("store_header was false, trying file right away")
Exception: store_header was false, trying file right away
Traceback (most recent call last):
  File "/gpfs_backup/tuck_data/atan2/framed-with-fountain/dnastorage/system/pipeline_dnafile.py", line 51, in open
    raise Exception("store_header was false, trying file right away")
Exception: store_header was false, trying file right away
Traceback (most recent call last):
  File "/gpfs_backup/tuck_data/atan2/framed-with-fountain/dnastorage/system/pipeline_dnafile.py", line 51, in open
    raise Exception("store_header was false, trying file right away")
Exception: store_header was false, trying file right away
Traceback (most recent call last):
  File "/gpfs_backup/tuck_data/atan2/framed-with-fountain/dnastorage/system/pipeline_dnafile.py", line 51, in open
    raise Exception("store_header was false, trying file right away")
Exception: store_header was false, trying file right away
Traceback (most recent call last):
  File "/gpfs_backup/tuck_data/atan2/framed-with-fountain/dnastorage/system/pipeline_dnafile.py", line 51, in open
    raise Exception("store_header was false, trying file right away")
Exception: store_header was false, trying file right away
Traceback (most recent call last):
  File "/gpfs_backup/tuck_data/atan2/framed-with-fountain/dnastorage/system/pipeline_dnafile.py", line 51, in open
    raise Exception("store_header was false, trying file right away")
Exception: store_header was false, trying file right away
Traceback (most recent call last):
  File "/gpfs_backup/tuck_data/atan2/framed-with-fountain/dnastorage/system/pipeline_dnafile.py", line 51, in open
    raise Exception("store_header was false, trying file right away")
Exception: store_header was false, trying file right away
Traceback (most recent call last):
  File "/gpfs_backup/tuck_data/atan2/framed-with-fountain/dnastorage/system/pipeline_dnafile.py", line 51, in open
    raise Exception("store_header was false, trying file right away")
Exception: store_header was false, trying file right away
Traceback (most recent call last):
  File "/gpfs_backup/tuck_data/atan2/framed-with-fountain/dnastorage/system/pipeline_dnafile.py", line 51, in open
    raise Exception("store_header was false, trying file right away")
Exception: store_header was false, trying file right away
Traceback (most recent call last):
  File "/gpfs_backup/tuck_data/atan2/framed-with-fountain/dnastorage/system/pipeline_dnafile.py", line 51, in open
    raise Exception("store_header was false, trying file right away")
Exception: store_header was false, trying file right away
Traceback (most recent call last):
  File "/gpfs_backup/tuck_data/atan2/framed-with-fountain/dnastorage/system/pipeline_dnafile.py", line 51, in open
    raise Exception("store_header was false, trying file right away")
Exception: store_header was false, trying file right away
Traceback (most recent call last):
  File "/gpfs_backup/tuck_data/atan2/framed-with-fountain/dnastorage/system/pipeline_dnafile.py", line 51, in open
    raise Exception("store_header was false, trying file right away")
Exception: store_header was false, trying file right away
Traceback (most recent call last):
  File "/gpfs_backup/tuck_data/atan2/framed-with-fountain/dnastorage/system/pipeline_dnafile.py", line 51, in open
    raise Exception("store_header was false, trying file right away")
Exception: store_header was false, trying file right away
Traceback (most recent call last):
  File "/gpfs_backup/tuck_data/atan2/framed-with-fountain/dnastorage/system/pipeline_dnafile.py", line 51, in open
    raise Exception("store_header was false, trying file right away")
Exception: store_header was false, trying file right away
Traceback (most recent call last):
  File "/gpfs_backup/tuck_data/atan2/framed-with-fountain/dnastorage/system/pipeline_dnafile.py", line 51, in open
    raise Exception("store_header was false, trying file right away")
Exception: store_header was false, trying file right away
Traceback (most recent call last):
  File "/gpfs_backup/tuck_data/atan2/framed-with-fountain/dnastorage/system/pipeline_dnafile.py", line 51, in open
    raise Exception("store_header was false, trying file right away")
Exception: store_header was false, trying file right away
Traceback (most recent call last):
  File "/gpfs_backup/tuck_data/atan2/framed-with-fountain/dnastorage/system/pipeline_dnafile.py", line 51, in open
    raise Exception("store_header was false, trying file right away")
Exception: store_header was false, trying file right away
Traceback (most recent call last):
  File "/gpfs_backup/tuck_data/atan2/framed-with-fountain/dnastorage/system/pipeline_dnafile.py", line 51, in open
    raise Exception("store_header was false, trying file right away")
Exception: store_header was false, trying file right away
Traceback (most recent call last):
  File "/gpfs_backup/tuck_data/atan2/framed-with-fountain/dnastorage/system/pipeline_dnafile.py", line 51, in open
    raise Exception("store_header was false, trying file right away")
Exception: store_header was false, trying file right away
Traceback (most recent call last):
  File "/gpfs_backup/tuck_data/atan2/framed-with-fountain/dnastorage/system/pipeline_dnafile.py", line 51, in open
    raise Exception("store_header was false, trying file right away")
Exception: store_header was false, trying file right away
Traceback (most recent call last):
  File "/gpfs_backup/tuck_data/atan2/framed-with-fountain/dnastorage/system/pipeline_dnafile.py", line 51, in open
    raise Exception("store_header was false, trying file right away")
Exception: store_header was false, trying file right away
Traceback (most recent call last):
  File "/gpfs_backup/tuck_data/atan2/framed-with-fountain/dnastorage/system/pipeline_dnafile.py", line 51, in open
    raise Exception("store_header was false, trying file right away")
Exception: store_header was false, trying file right away
Traceback (most recent call last):
  File "/gpfs_backup/tuck_data/atan2/framed-with-fountain/dnastorage/system/pipeline_dnafile.py", line 51, in open
    raise Exception("store_header was false, trying file right away")
Exception: store_header was false, trying file right away
Traceback (most recent call last):
  File "/gpfs_backup/tuck_data/atan2/framed-with-fountain/dnastorage/system/pipeline_dnafile.py", line 51, in open
    raise Exception("store_header was false, trying file right away")
Exception: store_header was false, trying file right away
Traceback (most recent call last):
  File "/gpfs_backup/tuck_data/atan2/framed-with-fountain/dnastorage/system/pipeline_dnafile.py", line 51, in open
    raise Exception("store_header was false, trying file right away")
Exception: store_header was false, trying file right away
Traceback (most recent call last):
  File "/gpfs_backup/tuck_data/atan2/framed-with-fountain/dnastorage/system/pipeline_dnafile.py", line 51, in open
    raise Exception("store_header was false, trying file right away")
Exception: store_header was false, trying file right away
Traceback (most recent call last):
  File "/gpfs_backup/tuck_data/atan2/framed-with-fountain/dnastorage/system/pipeline_dnafile.py", line 51, in open
    raise Exception("store_header was false, trying file right away")
Exception: store_header was false, trying file right away
Traceback (most recent call last):
  File "/gpfs_backup/tuck_data/atan2/framed-with-fountain/dnastorage/system/pipeline_dnafile.py", line 51, in open
    raise Exception("store_header was false, trying file right away")
Exception: store_header was false, trying file right away
Traceback (most recent call last):
  File "/gpfs_backup/tuck_data/atan2/framed-with-fountain/dnastorage/system/pipeline_dnafile.py", line 51, in open
    raise Exception("store_header was false, trying file right away")
Exception: store_header was false, trying file right away
Traceback (most recent call last):
  File "/gpfs_backup/tuck_data/atan2/framed-with-fountain/dnastorage/system/pipeline_dnafile.py", line 51, in open
    raise Exception("store_header was false, trying file right away")
Exception: store_header was false, trying file right away
Traceback (most recent call last):
  File "/gpfs_backup/tuck_data/atan2/framed-with-fountain/dnastorage/system/pipeline_dnafile.py", line 51, in open
    raise Exception("store_header was false, trying file right away")
Exception: store_header was false, trying file right away
Traceback (most recent call last):
  File "/gpfs_backup/tuck_data/atan2/framed-with-fountain/dnastorage/system/pipeline_dnafile.py", line 51, in open
    raise Exception("store_header was false, trying file right away")
Exception: store_header was false, trying file right away
Traceback (most recent call last):
  File "/gpfs_backup/tuck_data/atan2/framed-with-fountain/dnastorage/system/pipeline_dnafile.py", line 51, in open
    raise Exception("store_header was false, trying file right away")
Exception: store_header was false, trying file right away
Traceback (most recent call last):
  File "/gpfs_backup/tuck_data/atan2/framed-with-fountain/dnastorage/system/pipeline_dnafile.py", line 51, in open
    raise Exception("store_header was false, trying file right away")
Exception: store_header was false, trying file right away
Traceback (most recent call last):
  File "/gpfs_backup/tuck_data/atan2/framed-with-fountain/dnastorage/system/pipeline_dnafile.py", line 51, in open
    raise Exception("store_header was false, trying file right away")
Exception: store_header was false, trying file right away
Traceback (most recent call last):
  File "/gpfs_backup/tuck_data/atan2/framed-with-fountain/dnastorage/system/pipeline_dnafile.py", line 51, in open
    raise Exception("store_header was false, trying file right away")
Exception: store_header was false, trying file right away
Traceback (most recent call last):
  File "/gpfs_backup/tuck_data/atan2/framed-with-fountain/dnastorage/system/pipeline_dnafile.py", line 51, in open
    raise Exception("store_header was false, trying file right away")
Exception: store_header was false, trying file right away
Traceback (most recent call last):
  File "/gpfs_backup/tuck_data/atan2/framed-with-fountain/dnastorage/system/pipeline_dnafile.py", line 51, in open
    raise Exception("store_header was false, trying file right away")
Exception: store_header was false, trying file right away
Traceback (most recent call last):
  File "/gpfs_backup/tuck_data/atan2/framed-with-fountain/dnastorage/system/pipeline_dnafile.py", line 51, in open
    raise Exception("store_header was false, trying file right away")
Exception: store_header was false, trying file right away
Traceback (most recent call last):
  File "/gpfs_backup/tuck_data/atan2/framed-with-fountain/dnastorage/system/pipeline_dnafile.py", line 51, in open
    raise Exception("store_header was false, trying file right away")
Exception: store_header was false, trying file right away
Traceback (most recent call last):
  File "/gpfs_backup/tuck_data/atan2/framed-with-fountain/dnastorage/system/pipeline_dnafile.py", line 51, in open
    raise Exception("store_header was false, trying file right away")
Exception: store_header was false, trying file right away
Traceback (most recent call last):
  File "/gpfs_backup/tuck_data/atan2/framed-with-fountain/dnastorage/system/pipeline_dnafile.py", line 51, in open
    raise Exception("store_header was false, trying file right away")
Exception: store_header was false, trying file right away
Traceback (most recent call last):
  File "/gpfs_backup/tuck_data/atan2/framed-with-fountain/dnastorage/system/pipeline_dnafile.py", line 51, in open
    raise Exception("store_header was false, trying file right away")
Exception: store_header was false, trying file right away
Traceback (most recent call last):
  File "/gpfs_backup/tuck_data/atan2/framed-with-fountain/dnastorage/system/pipeline_dnafile.py", line 51, in open
    raise Exception("store_header was false, trying file right away")
Exception: store_header was false, trying file right away
Traceback (most recent call last):
  File "/gpfs_backup/tuck_data/atan2/framed-with-fountain/dnastorage/system/pipeline_dnafile.py", line 51, in open
    raise Exception("store_header was false, trying file right away")
Exception: store_header was false, trying file right away

signal (11): Segmentation fault
in expression starting at none:0
impi_free at /usr/local/apps/intel/oneapi-2024/mpi/2021.12/lib/libmpi.so.12 (unknown line)
unknown function (ip: 0x14c2a76bf47f)
Allocations: 40857076 (Pool: 40846950; Big: 10126); GC: 50
