Traceback (most recent call last):
  File "/gpfs_backup/tuck_data/atan2/framed-with-fountain/dnastorage/system/pipeline_dnafile.py", line 51, in open
    raise Exception("store_header was false, trying file right away")
Exception: store_header was false, trying file right away
Traceback (most recent call last):
  File "/gpfs_backup/tuck_data/atan2/framed-with-fountain/dnastorage/system/pipeline_dnafile.py", line 51, in open
    raise Exception("store_header was false, trying file right away")
Exception: store_header was false, trying file right away
Traceback (most recent call last):
  File "/gpfs_backup/tuck_data/atan2/framed-with-fountain/dnastorage/system/pipeline_dnafile.py", line 51, in open
    raise Exception("store_header was false, trying file right away")
Exception: store_header was false, trying file right away
Traceback (most recent call last):
  File "/gpfs_backup/tuck_data/atan2/framed-with-fountain/dnastorage/system/pipeline_dnafile.py", line 51, in open
    raise Exception("store_header was false, trying file right away")
Exception: store_header was false, trying file right away
Traceback (most recent call last):
  File "/gpfs_backup/tuck_data/atan2/framed-with-fountain/dnastorage/system/pipeline_dnafile.py", line 51, in open
    raise Exception("store_header was false, trying file right away")
Exception: store_header was false, trying file right away
Traceback (most recent call last):
  File "/gpfs_backup/tuck_data/atan2/framed-with-fountain/dnastorage/system/pipeline_dnafile.py", line 51, in open
    raise Exception("store_header was false, trying file right away")
Exception: store_header was false, trying file right away
Traceback (most recent call last):
  File "/gpfs_backup/tuck_data/atan2/framed-with-fountain/dnastorage/system/pipeline_dnafile.py", line 51, in open
    raise Exception("store_header was false, trying file right away")
Exception: store_header was false, trying file right away
Traceback (most recent call last):
  File "/gpfs_backup/tuck_data/atan2/framed-with-fountain/dnastorage/system/pipeline_dnafile.py", line 51, in open
    raise Exception("store_header was false, trying file right away")
Exception: store_header was false, trying file right away
Traceback (most recent call last):
  File "/gpfs_backup/tuck_data/atan2/framed-with-fountain/dnastorage/system/pipeline_dnafile.py", line 51, in open
    raise Exception("store_header was false, trying file right away")
Exception: store_header was false, trying file right away
Traceback (most recent call last):
  File "/gpfs_backup/tuck_data/atan2/framed-with-fountain/dnastorage/system/pipeline_dnafile.py", line 51, in open
    raise Exception("store_header was false, trying file right away")
Exception: store_header was false, trying file right away
Traceback (most recent call last):
  File "/gpfs_backup/tuck_data/atan2/framed-with-fountain/dnastorage/system/pipeline_dnafile.py", line 51, in open
    raise Exception("store_header was false, trying file right away")
Exception: store_header was false, trying file right away
Traceback (most recent call last):
  File "/gpfs_backup/tuck_data/atan2/framed-with-fountain/dnastorage/system/pipeline_dnafile.py", line 51, in open
    raise Exception("store_header was false, trying file right away")
Exception: store_header was false, trying file right away
Traceback (most recent call last):
  File "/gpfs_backup/tuck_data/atan2/framed-with-fountain/dnastorage/system/pipeline_dnafile.py", line 51, in open
    raise Exception("store_header was false, trying file right away")
Exception: store_header was false, trying file right away
Traceback (most recent call last):
  File "/gpfs_backup/tuck_data/atan2/framed-with-fountain/dnastorage/system/pipeline_dnafile.py", line 51, in open
    raise Exception("store_header was false, trying file right away")
Exception: store_header was false, trying file right away
Traceback (most recent call last):
  File "/gpfs_backup/tuck_data/atan2/framed-with-fountain/dnastorage/system/pipeline_dnafile.py", line 51, in open
    raise Exception("store_header was false, trying file right away")
Exception: store_header was false, trying file right away
Traceback (most recent call last):
  File "/gpfs_backup/tuck_data/atan2/framed-with-fountain/dnastorage/system/pipeline_dnafile.py", line 51, in open
    raise Exception("store_header was false, trying file right away")
Exception: store_header was false, trying file right away
Traceback (most recent call last):
  File "/gpfs_backup/tuck_data/atan2/framed-with-fountain/dnastorage/system/pipeline_dnafile.py", line 51, in open
    raise Exception("store_header was false, trying file right away")
Exception: store_header was false, trying file right away
Traceback (most recent call last):
  File "/gpfs_backup/tuck_data/atan2/framed-with-fountain/dnastorage/system/pipeline_dnafile.py", line 51, in open
    raise Exception("store_header was false, trying file right away")
Exception: store_header was false, trying file right away
Traceback (most recent call last):
  File "/gpfs_backup/tuck_data/atan2/framed-with-fountain/dnastorage/system/pipeline_dnafile.py", line 51, in open
    raise Exception("store_header was false, trying file right away")
Exception: store_header was false, trying file right away
Traceback (most recent call last):
  File "/gpfs_backup/tuck_data/atan2/framed-with-fountain/dnastorage/system/pipeline_dnafile.py", line 51, in open
    raise Exception("store_header was false, trying file right away")
Exception: store_header was false, trying file right away
Traceback (most recent call last):
  File "/gpfs_backup/tuck_data/atan2/framed-with-fountain/dnastorage/system/pipeline_dnafile.py", line 51, in open
    raise Exception("store_header was false, trying file right away")
Exception: store_header was false, trying file right away
Traceback (most recent call last):
  File "/gpfs_backup/tuck_data/atan2/framed-with-fountain/dnastorage/system/pipeline_dnafile.py", line 51, in open
    raise Exception("store_header was false, trying file right away")
Exception: store_header was false, trying file right away
Traceback (most recent call last):
  File "/gpfs_backup/tuck_data/atan2/framed-with-fountain/dnastorage/system/pipeline_dnafile.py", line 51, in open
    raise Exception("store_header was false, trying file right away")
Exception: store_header was false, trying file right away
Traceback (most recent call last):
  File "/gpfs_backup/tuck_data/atan2/framed-with-fountain/dnastorage/system/pipeline_dnafile.py", line 51, in open
    raise Exception("store_header was false, trying file right away")
Exception: store_header was false, trying file right away
Traceback (most recent call last):
  File "/gpfs_backup/tuck_data/atan2/framed-with-fountain/dnastorage/system/pipeline_dnafile.py", line 51, in open
    raise Exception("store_header was false, trying file right away")
Exception: store_header was false, trying file right away
Traceback (most recent call last):
  File "/gpfs_backup/tuck_data/atan2/framed-with-fountain/dnastorage/system/pipeline_dnafile.py", line 51, in open
    raise Exception("store_header was false, trying file right away")
Exception: store_header was false, trying file right away
Traceback (most recent call last):
  File "/gpfs_backup/tuck_data/atan2/framed-with-fountain/dnastorage/system/pipeline_dnafile.py", line 51, in open
    raise Exception("store_header was false, trying file right away")
Exception: store_header was false, trying file right away
Traceback (most recent call last):
  File "/gpfs_backup/tuck_data/atan2/framed-with-fountain/dnastorage/system/pipeline_dnafile.py", line 51, in open
    raise Exception("store_header was false, trying file right away")
Exception: store_header was false, trying file right away
Traceback (most recent call last):
  File "/gpfs_backup/tuck_data/atan2/framed-with-fountain/dnastorage/system/pipeline_dnafile.py", line 51, in open
    raise Exception("store_header was false, trying file right away")
Exception: store_header was false, trying file right away
Traceback (most recent call last):
  File "/gpfs_backup/tuck_data/atan2/framed-with-fountain/dnastorage/system/pipeline_dnafile.py", line 51, in open
    raise Exception("store_header was false, trying file right away")
Exception: store_header was false, trying file right away
Traceback (most recent call last):
  File "/gpfs_backup/tuck_data/atan2/framed-with-fountain/dnastorage/system/pipeline_dnafile.py", line 51, in open
    raise Exception("store_header was false, trying file right away")
Exception: store_header was false, trying file right away
Traceback (most recent call last):
  File "/gpfs_backup/tuck_data/atan2/framed-with-fountain/dnastorage/system/pipeline_dnafile.py", line 51, in open
    raise Exception("store_header was false, trying file right away")
Exception: store_header was false, trying file right away
Traceback (most recent call last):
  File "/gpfs_backup/tuck_data/atan2/framed-with-fountain/dnastorage/system/pipeline_dnafile.py", line 51, in open
    raise Exception("store_header was false, trying file right away")
Exception: store_header was false, trying file right away
Traceback (most recent call last):
  File "/gpfs_backup/tuck_data/atan2/framed-with-fountain/dnastorage/system/pipeline_dnafile.py", line 51, in open
    raise Exception("store_header was false, trying file right away")
Exception: store_header was false, trying file right away
Traceback (most recent call last):
  File "/gpfs_backup/tuck_data/atan2/framed-with-fountain/dnastorage/system/pipeline_dnafile.py", line 51, in open
    raise Exception("store_header was false, trying file right away")
Exception: store_header was false, trying file right away
Traceback (most recent call last):
  File "/gpfs_backup/tuck_data/atan2/framed-with-fountain/dnastorage/system/pipeline_dnafile.py", line 51, in open
    raise Exception("store_header was false, trying file right away")
Exception: store_header was false, trying file right away
Traceback (most recent call last):
  File "/gpfs_backup/tuck_data/atan2/framed-with-fountain/dnastorage/system/pipeline_dnafile.py", line 51, in open
    raise Exception("store_header was false, trying file right away")
Exception: store_header was false, trying file right away
Traceback (most recent call last):
  File "/gpfs_backup/tuck_data/atan2/framed-with-fountain/dnastorage/system/pipeline_dnafile.py", line 51, in open
    raise Exception("store_header was false, trying file right away")
Exception: store_header was false, trying file right away
Traceback (most recent call last):
  File "/gpfs_backup/tuck_data/atan2/framed-with-fountain/dnastorage/system/pipeline_dnafile.py", line 51, in open
    raise Exception("store_header was false, trying file right away")
Exception: store_header was false, trying file right away
Traceback (most recent call last):
  File "/gpfs_backup/tuck_data/atan2/framed-with-fountain/dnastorage/system/pipeline_dnafile.py", line 51, in open
    raise Exception("store_header was false, trying file right away")
Exception: store_header was false, trying file right away
Traceback (most recent call last):
  File "/gpfs_backup/tuck_data/atan2/framed-with-fountain/dnastorage/system/pipeline_dnafile.py", line 51, in open
    raise Exception("store_header was false, trying file right away")
Exception: store_header was false, trying file right away
Traceback (most recent call last):
  File "/gpfs_backup/tuck_data/atan2/framed-with-fountain/dnastorage/system/pipeline_dnafile.py", line 51, in open
    raise Exception("store_header was false, trying file right away")
Exception: store_header was false, trying file right away
Traceback (most recent call last):
  File "/gpfs_backup/tuck_data/atan2/framed-with-fountain/dnastorage/system/pipeline_dnafile.py", line 51, in open
    raise Exception("store_header was false, trying file right away")
Exception: store_header was false, trying file right away
Traceback (most recent call last):
  File "/gpfs_backup/tuck_data/atan2/framed-with-fountain/dnastorage/system/pipeline_dnafile.py", line 51, in open
    raise Exception("store_header was false, trying file right away")
Exception: store_header was false, trying file right away
Traceback (most recent call last):
  File "/gpfs_backup/tuck_data/atan2/framed-with-fountain/dnastorage/system/pipeline_dnafile.py", line 51, in open
    raise Exception("store_header was false, trying file right away")
Exception: store_header was false, trying file right away
Traceback (most recent call last):
  File "/gpfs_backup/tuck_data/atan2/framed-with-fountain/dnastorage/system/pipeline_dnafile.py", line 51, in open
    raise Exception("store_header was false, trying file right away")
Exception: store_header was false, trying file right away
Traceback (most recent call last):
  File "/gpfs_backup/tuck_data/atan2/framed-with-fountain/dnastorage/system/pipeline_dnafile.py", line 51, in open
    raise Exception("store_header was false, trying file right away")
Exception: store_header was false, trying file right away
Traceback (most recent call last):
  File "/gpfs_backup/tuck_data/atan2/framed-with-fountain/dnastorage/system/pipeline_dnafile.py", line 51, in open
    raise Exception("store_header was false, trying file right away")
Exception: store_header was false, trying file right away
Traceback (most recent call last):
  File "/gpfs_backup/tuck_data/atan2/framed-with-fountain/dnastorage/system/pipeline_dnafile.py", line 51, in open
    raise Exception("store_header was false, trying file right away")
Exception: store_header was false, trying file right away
Traceback (most recent call last):
  File "/gpfs_backup/tuck_data/atan2/framed-with-fountain/dnastorage/system/pipeline_dnafile.py", line 51, in open
    raise Exception("store_header was false, trying file right away")
Exception: store_header was false, trying file right away
Traceback (most recent call last):
  File "/gpfs_backup/tuck_data/atan2/framed-with-fountain/dnastorage/system/pipeline_dnafile.py", line 51, in open
    raise Exception("store_header was false, trying file right away")
Exception: store_header was false, trying file right away
Traceback (most recent call last):
  File "/gpfs_backup/tuck_data/atan2/framed-with-fountain/dnastorage/system/pipeline_dnafile.py", line 51, in open
    raise Exception("store_header was false, trying file right away")
Exception: store_header was false, trying file right away
Traceback (most recent call last):
  File "/gpfs_backup/tuck_data/atan2/framed-with-fountain/dnastorage/system/pipeline_dnafile.py", line 51, in open
    raise Exception("store_header was false, trying file right away")
Exception: store_header was false, trying file right away
Traceback (most recent call last):
  File "/gpfs_backup/tuck_data/atan2/framed-with-fountain/dnastorage/system/pipeline_dnafile.py", line 51, in open
    raise Exception("store_header was false, trying file right away")
Exception: store_header was false, trying file right away
Traceback (most recent call last):
  File "/gpfs_backup/tuck_data/atan2/framed-with-fountain/dnastorage/system/pipeline_dnafile.py", line 51, in open
    raise Exception("store_header was false, trying file right away")
Exception: store_header was false, trying file right away
Traceback (most recent call last):
  File "/gpfs_backup/tuck_data/atan2/framed-with-fountain/dnastorage/system/pipeline_dnafile.py", line 51, in open
    raise Exception("store_header was false, trying file right away")
Exception: store_header was false, trying file right away
Traceback (most recent call last):
  File "/gpfs_backup/tuck_data/atan2/framed-with-fountain/dnastorage/system/pipeline_dnafile.py", line 51, in open
    raise Exception("store_header was false, trying file right away")
Exception: store_header was false, trying file right away
Traceback (most recent call last):
  File "/gpfs_backup/tuck_data/atan2/framed-with-fountain/dnastorage/system/pipeline_dnafile.py", line 51, in open
    raise Exception("store_header was false, trying file right away")
Exception: store_header was false, trying file right away
Traceback (most recent call last):
  File "/gpfs_backup/tuck_data/atan2/framed-with-fountain/dnastorage/system/pipeline_dnafile.py", line 51, in open
    raise Exception("store_header was false, trying file right away")
Exception: store_header was false, trying file right away
Traceback (most recent call last):
  File "/gpfs_backup/tuck_data/atan2/framed-with-fountain/dnastorage/system/pipeline_dnafile.py", line 51, in open
    raise Exception("store_header was false, trying file right away")
Exception: store_header was false, trying file right away
Traceback (most recent call last):
  File "/gpfs_backup/tuck_data/atan2/framed-with-fountain/dnastorage/system/pipeline_dnafile.py", line 51, in open
    raise Exception("store_header was false, trying file right away")
Exception: store_header was false, trying file right away
Traceback (most recent call last):
  File "/gpfs_backup/tuck_data/atan2/framed-with-fountain/dnastorage/system/pipeline_dnafile.py", line 51, in open
    raise Exception("store_header was false, trying file right away")
Exception: store_header was false, trying file right away
Traceback (most recent call last):
  File "/gpfs_backup/tuck_data/atan2/framed-with-fountain/dnastorage/system/pipeline_dnafile.py", line 51, in open
    raise Exception("store_header was false, trying file right away")
Exception: store_header was false, trying file right away
Traceback (most recent call last):
  File "/gpfs_backup/tuck_data/atan2/framed-with-fountain/dnastorage/system/pipeline_dnafile.py", line 51, in open
    raise Exception("store_header was false, trying file right away")
Exception: store_header was false, trying file right away
Traceback (most recent call last):
  File "/gpfs_backup/tuck_data/atan2/framed-with-fountain/dnastorage/system/pipeline_dnafile.py", line 51, in open
    raise Exception("store_header was false, trying file right away")
Exception: store_header was false, trying file right away
Traceback (most recent call last):
  File "/gpfs_backup/tuck_data/atan2/framed-with-fountain/dnastorage/system/pipeline_dnafile.py", line 51, in open
    raise Exception("store_header was false, trying file right away")
Exception: store_header was false, trying file right away
Traceback (most recent call last):
  File "/gpfs_backup/tuck_data/atan2/framed-with-fountain/dnastorage/system/pipeline_dnafile.py", line 51, in open
    raise Exception("store_header was false, trying file right away")
Exception: store_header was false, trying file right away
Traceback (most recent call last):
  File "/gpfs_backup/tuck_data/atan2/framed-with-fountain/dnastorage/system/pipeline_dnafile.py", line 51, in open
    raise Exception("store_header was false, trying file right away")
Exception: store_header was false, trying file right away
Traceback (most recent call last):
  File "/gpfs_backup/tuck_data/atan2/framed-with-fountain/dnastorage/system/pipeline_dnafile.py", line 51, in open
    raise Exception("store_header was false, trying file right away")
Exception: store_header was false, trying file right away
Traceback (most recent call last):
  File "/gpfs_backup/tuck_data/atan2/framed-with-fountain/dnastorage/system/pipeline_dnafile.py", line 51, in open
    raise Exception("store_header was false, trying file right away")
Exception: store_header was false, trying file right away
Traceback (most recent call last):
  File "/gpfs_backup/tuck_data/atan2/framed-with-fountain/dnastorage/system/pipeline_dnafile.py", line 51, in open
    raise Exception("store_header was false, trying file right away")
Exception: store_header was false, trying file right away
Traceback (most recent call last):
  File "/gpfs_backup/tuck_data/atan2/framed-with-fountain/dnastorage/system/pipeline_dnafile.py", line 51, in open
    raise Exception("store_header was false, trying file right away")
Exception: store_header was false, trying file right away
Traceback (most recent call last):
  File "/gpfs_backup/tuck_data/atan2/framed-with-fountain/dnastorage/system/pipeline_dnafile.py", line 51, in open
    raise Exception("store_header was false, trying file right away")
Exception: store_header was false, trying file right away
Traceback (most recent call last):
  File "/gpfs_backup/tuck_data/atan2/framed-with-fountain/dnastorage/system/pipeline_dnafile.py", line 51, in open
    raise Exception("store_header was false, trying file right away")
Exception: store_header was false, trying file right away
Traceback (most recent call last):
  File "/gpfs_backup/tuck_data/atan2/framed-with-fountain/dnastorage/system/pipeline_dnafile.py", line 51, in open
    raise Exception("store_header was false, trying file right away")
Exception: store_header was false, trying file right away
Traceback (most recent call last):
  File "/gpfs_backup/tuck_data/atan2/framed-with-fountain/dnastorage/system/pipeline_dnafile.py", line 51, in open
    raise Exception("store_header was false, trying file right away")
Exception: store_header was false, trying file right away
Traceback (most recent call last):
  File "/gpfs_backup/tuck_data/atan2/framed-with-fountain/dnastorage/system/pipeline_dnafile.py", line 51, in open
    raise Exception("store_header was false, trying file right away")
Exception: store_header was false, trying file right away
Traceback (most recent call last):
  File "/gpfs_backup/tuck_data/atan2/framed-with-fountain/dnastorage/system/pipeline_dnafile.py", line 51, in open
    raise Exception("store_header was false, trying file right away")
Exception: store_header was false, trying file right away
Traceback (most recent call last):
  File "/gpfs_backup/tuck_data/atan2/framed-with-fountain/dnastorage/system/pipeline_dnafile.py", line 51, in open
    raise Exception("store_header was false, trying file right away")
Exception: store_header was false, trying file right away
Traceback (most recent call last):
  File "/gpfs_backup/tuck_data/atan2/framed-with-fountain/dnastorage/system/pipeline_dnafile.py", line 51, in open
    raise Exception("store_header was false, trying file right away")
Exception: store_header was false, trying file right away
Traceback (most recent call last):
  File "/gpfs_backup/tuck_data/atan2/framed-with-fountain/dnastorage/system/pipeline_dnafile.py", line 51, in open
    raise Exception("store_header was false, trying file right away")
Exception: store_header was false, trying file right away
Traceback (most recent call last):
  File "/gpfs_backup/tuck_data/atan2/framed-with-fountain/dnastorage/system/pipeline_dnafile.py", line 51, in open
    raise Exception("store_header was false, trying file right away")
Exception: store_header was false, trying file right away
Traceback (most recent call last):
  File "/gpfs_backup/tuck_data/atan2/framed-with-fountain/dnastorage/system/pipeline_dnafile.py", line 51, in open
    raise Exception("store_header was false, trying file right away")
Exception: store_header was false, trying file right away
Traceback (most recent call last):
  File "/gpfs_backup/tuck_data/atan2/framed-with-fountain/dnastorage/system/pipeline_dnafile.py", line 51, in open
    raise Exception("store_header was false, trying file right away")
Exception: store_header was false, trying file right away
Traceback (most recent call last):
  File "/gpfs_backup/tuck_data/atan2/framed-with-fountain/dnastorage/system/pipeline_dnafile.py", line 51, in open
    raise Exception("store_header was false, trying file right away")
Exception: store_header was false, trying file right away
Traceback (most recent call last):
  File "/gpfs_backup/tuck_data/atan2/framed-with-fountain/dnastorage/system/pipeline_dnafile.py", line 51, in open
    raise Exception("store_header was false, trying file right away")
Exception: store_header was false, trying file right away
Traceback (most recent call last):
  File "/gpfs_backup/tuck_data/atan2/framed-with-fountain/dnastorage/system/pipeline_dnafile.py", line 51, in open
    raise Exception("store_header was false, trying file right away")
Exception: store_header was false, trying file right away
Traceback (most recent call last):
  File "/gpfs_backup/tuck_data/atan2/framed-with-fountain/dnastorage/system/pipeline_dnafile.py", line 51, in open
    raise Exception("store_header was false, trying file right away")
Exception: store_header was false, trying file right away
Traceback (most recent call last):
  File "/gpfs_backup/tuck_data/atan2/framed-with-fountain/dnastorage/system/pipeline_dnafile.py", line 51, in open
    raise Exception("store_header was false, trying file right away")
Exception: store_header was false, trying file right away
Traceback (most recent call last):
  File "/gpfs_backup/tuck_data/atan2/framed-with-fountain/dnastorage/system/pipeline_dnafile.py", line 51, in open
    raise Exception("store_header was false, trying file right away")
Exception: store_header was false, trying file right away
Traceback (most recent call last):
  File "/gpfs_backup/tuck_data/atan2/framed-with-fountain/dnastorage/system/pipeline_dnafile.py", line 51, in open
    raise Exception("store_header was false, trying file right away")
Exception: store_header was false, trying file right away
Traceback (most recent call last):
  File "/gpfs_backup/tuck_data/atan2/framed-with-fountain/dnastorage/system/pipeline_dnafile.py", line 51, in open
    raise Exception("store_header was false, trying file right away")
Exception: store_header was false, trying file right away
Traceback (most recent call last):
  File "/gpfs_backup/tuck_data/atan2/framed-with-fountain/dnastorage/system/pipeline_dnafile.py", line 51, in open
    raise Exception("store_header was false, trying file right away")
Exception: store_header was false, trying file right away
Traceback (most recent call last):
  File "/gpfs_backup/tuck_data/atan2/framed-with-fountain/dnastorage/system/pipeline_dnafile.py", line 51, in open
    raise Exception("store_header was false, trying file right away")
Exception: store_header was false, trying file right away
Traceback (most recent call last):
  File "/gpfs_backup/tuck_data/atan2/framed-with-fountain/dnastorage/system/pipeline_dnafile.py", line 51, in open
    raise Exception("store_header was false, trying file right away")
Exception: store_header was false, trying file right away
Traceback (most recent call last):
  File "/gpfs_backup/tuck_data/atan2/framed-with-fountain/dnastorage/system/pipeline_dnafile.py", line 51, in open
    raise Exception("store_header was false, trying file right away")
Exception: store_header was false, trying file right away
Traceback (most recent call last):
  File "/gpfs_backup/tuck_data/atan2/framed-with-fountain/dnastorage/system/pipeline_dnafile.py", line 51, in open
    raise Exception("store_header was false, trying file right away")
Exception: store_header was false, trying file right away
Traceback (most recent call last):
  File "/gpfs_backup/tuck_data/atan2/framed-with-fountain/dnastorage/system/pipeline_dnafile.py", line 51, in open
    raise Exception("store_header was false, trying file right away")
Exception: store_header was false, trying file right away
Traceback (most recent call last):
  File "/gpfs_backup/tuck_data/atan2/framed-with-fountain/dnastorage/system/pipeline_dnafile.py", line 51, in open
    raise Exception("store_header was false, trying file right away")
Exception: store_header was false, trying file right away
Traceback (most recent call last):
  File "/gpfs_backup/tuck_data/atan2/framed-with-fountain/dnastorage/system/pipeline_dnafile.py", line 51, in open
    raise Exception("store_header was false, trying file right away")
Exception: store_header was false, trying file right away
Traceback (most recent call last):
  File "/gpfs_backup/tuck_data/atan2/framed-with-fountain/dnastorage/system/pipeline_dnafile.py", line 51, in open
    raise Exception("store_header was false, trying file right away")
Exception: store_header was false, trying file right away
Traceback (most recent call last):
  File "/gpfs_backup/tuck_data/atan2/framed-with-fountain/dnastorage/system/pipeline_dnafile.py", line 51, in open
    raise Exception("store_header was false, trying file right away")
Exception: store_header was false, trying file right away
Traceback (most recent call last):
  File "/gpfs_backup/tuck_data/atan2/framed-with-fountain/dnastorage/system/pipeline_dnafile.py", line 51, in open
    raise Exception("store_header was false, trying file right away")
Exception: store_header was false, trying file right away
Traceback (most recent call last):
  File "/gpfs_backup/tuck_data/atan2/framed-with-fountain/dnastorage/system/pipeline_dnafile.py", line 51, in open
    raise Exception("store_header was false, trying file right away")
Exception: store_header was false, trying file right away
Traceback (most recent call last):
  File "/gpfs_backup/tuck_data/atan2/framed-with-fountain/dnastorage/system/pipeline_dnafile.py", line 51, in open
    raise Exception("store_header was false, trying file right away")
Exception: store_header was false, trying file right away
Traceback (most recent call last):
  File "/gpfs_backup/tuck_data/atan2/framed-with-fountain/dnastorage/system/pipeline_dnafile.py", line 51, in open
    raise Exception("store_header was false, trying file right away")
Exception: store_header was false, trying file right away
Traceback (most recent call last):
  File "/gpfs_backup/tuck_data/atan2/framed-with-fountain/dnastorage/system/pipeline_dnafile.py", line 51, in open
    raise Exception("store_header was false, trying file right away")
Exception: store_header was false, trying file right away
Traceback (most recent call last):
  File "/gpfs_backup/tuck_data/atan2/framed-with-fountain/dnastorage/system/pipeline_dnafile.py", line 51, in open
    raise Exception("store_header was false, trying file right away")
Traceback (most recent call last):
  File "/gpfs_backup/tuck_data/atan2/framed-with-fountain/dnastorage/system/pipeline_dnafile.py", line 51, in open
    raise Exception("store_header was false, trying file right away")
Exception: store_header was false, trying file right away
Exception: store_header was false, trying file right away
Traceback (most recent call last):
  File "/gpfs_backup/tuck_data/atan2/framed-with-fountain/dnastorage/system/pipeline_dnafile.py", line 51, in open
    raise Exception("store_header was false, trying file right away")
Exception: store_header was false, trying file right away
Traceback (most recent call last):
  File "/gpfs_backup/tuck_data/atan2/framed-with-fountain/dnastorage/system/pipeline_dnafile.py", line 51, in open
    raise Exception("store_header was false, trying file right away")
Exception: store_header was false, trying file right away
Traceback (most recent call last):
  File "/gpfs_backup/tuck_data/atan2/framed-with-fountain/dnastorage/system/pipeline_dnafile.py", line 51, in open
    raise Exception("store_header was false, trying file right away")
Exception: store_header was false, trying file right away
Traceback (most recent call last):
  File "/gpfs_backup/tuck_data/atan2/framed-with-fountain/dnastorage/system/pipeline_dnafile.py", line 51, in open
    raise Exception("store_header was false, trying file right away")
Exception: store_header was false, trying file right away
Traceback (most recent call last):
  File "/gpfs_backup/tuck_data/atan2/framed-with-fountain/dnastorage/system/pipeline_dnafile.py", line 51, in open
    raise Exception("store_header was false, trying file right away")
Exception: store_header was false, trying file right away
Traceback (most recent call last):
  File "/gpfs_backup/tuck_data/atan2/framed-with-fountain/dnastorage/system/pipeline_dnafile.py", line 51, in open
    raise Exception("store_header was false, trying file right away")
Exception: store_header was false, trying file right away
Traceback (most recent call last):
  File "/gpfs_backup/tuck_data/atan2/framed-with-fountain/dnastorage/system/pipeline_dnafile.py", line 51, in open
    raise Exception("store_header was false, trying file right away")
Exception: store_header was false, trying file right away
Traceback (most recent call last):
  File "/gpfs_backup/tuck_data/atan2/framed-with-fountain/dnastorage/system/pipeline_dnafile.py", line 51, in open
    raise Exception("store_header was false, trying file right away")
Exception: store_header was false, trying file right away
Traceback (most recent call last):
  File "/gpfs_backup/tuck_data/atan2/framed-with-fountain/dnastorage/system/pipeline_dnafile.py", line 51, in open
    raise Exception("store_header was false, trying file right away")
Exception: store_header was false, trying file right away
Traceback (most recent call last):
  File "/gpfs_backup/tuck_data/atan2/framed-with-fountain/dnastorage/system/pipeline_dnafile.py", line 51, in open
    raise Exception("store_header was false, trying file right away")
Exception: store_header was false, trying file right away
Traceback (most recent call last):
  File "/gpfs_backup/tuck_data/atan2/framed-with-fountain/dnastorage/system/pipeline_dnafile.py", line 51, in open
    raise Exception("store_header was false, trying file right away")
Exception: store_header was false, trying file right away
Traceback (most recent call last):
  File "/gpfs_backup/tuck_data/atan2/framed-with-fountain/dnastorage/system/pipeline_dnafile.py", line 51, in open
    raise Exception("store_header was false, trying file right away")
Exception: store_header was false, trying file right away
Traceback (most recent call last):
  File "/gpfs_backup/tuck_data/atan2/framed-with-fountain/dnastorage/system/pipeline_dnafile.py", line 51, in open
    raise Exception("store_header was false, trying file right away")
Exception: store_header was false, trying file right away
Traceback (most recent call last):
  File "/gpfs_backup/tuck_data/atan2/framed-with-fountain/dnastorage/system/pipeline_dnafile.py", line 51, in open
    raise Exception("store_header was false, trying file right away")
Exception: store_header was false, trying file right away
Traceback (most recent call last):
  File "/gpfs_backup/tuck_data/atan2/framed-with-fountain/dnastorage/system/pipeline_dnafile.py", line 51, in open
    raise Exception("store_header was false, trying file right away")
Exception: store_header was false, trying file right away
Traceback (most recent call last):
  File "/gpfs_backup/tuck_data/atan2/framed-with-fountain/dnastorage/system/pipeline_dnafile.py", line 51, in open
    raise Exception("store_header was false, trying file right away")
Exception: store_header was false, trying file right away
Traceback (most recent call last):
  File "/gpfs_backup/tuck_data/atan2/framed-with-fountain/dnastorage/system/pipeline_dnafile.py", line 51, in open
    raise Exception("store_header was false, trying file right away")
Exception: store_header was false, trying file right away
Traceback (most recent call last):
  File "/gpfs_backup/tuck_data/atan2/framed-with-fountain/dnastorage/system/pipeline_dnafile.py", line 51, in open
    raise Exception("store_header was false, trying file right away")
Exception: store_header was false, trying file right away
Traceback (most recent call last):
  File "/gpfs_backup/tuck_data/atan2/framed-with-fountain/dnastorage/system/pipeline_dnafile.py", line 51, in open
    raise Exception("store_header was false, trying file right away")
Exception: store_header was false, trying file right away
