Traceback (most recent call last):
  File "/gpfs_backup/tuck_data/atan2/framed-with-fountain/dnastorage/system/pipeline_dnafile.py", line 51, in open
    raise Exception("store_header was false, trying file right away")
Exception: store_header was false, trying file right away
Traceback (most recent call last):
  File "/gpfs_backup/tuck_data/atan2/framed-with-fountain/dnastorage/system/pipeline_dnafile.py", line 51, in open
    raise Exception("store_header was false, trying file right away")
Exception: store_header was false, trying file right away
Traceback (most recent call last):
  File "/gpfs_backup/tuck_data/atan2/framed-with-fountain/dnastorage/system/pipeline_dnafile.py", line 51, in open
    raise Exception("store_header was false, trying file right away")
Exception: store_header was false, trying file right away
Traceback (most recent call last):
  File "/gpfs_backup/tuck_data/atan2/framed-with-fountain/dnastorage/system/pipeline_dnafile.py", line 51, in open
    raise Exception("store_header was false, trying file right away")
Exception: store_header was false, trying file right away
Traceback (most recent call last):
  File "/gpfs_backup/tuck_data/atan2/framed-with-fountain/dnastorage/system/pipeline_dnafile.py", line 51, in open
    raise Exception("store_header was false, trying file right away")
Exception: store_header was false, trying file right away
Traceback (most recent call last):
  File "/gpfs_backup/tuck_data/atan2/framed-with-fountain/dnastorage/system/pipeline_dnafile.py", line 51, in open
    raise Exception("store_header was false, trying file right away")
Exception: store_header was false, trying file right away
Traceback (most recent call last):
  File "/gpfs_backup/tuck_data/atan2/framed-with-fountain/dnastorage/system/pipeline_dnafile.py", line 51, in open
    raise Exception("store_header was false, trying file right away")
Exception: store_header was false, trying file right away
Traceback (most recent call last):
  File "/gpfs_backup/tuck_data/atan2/framed-with-fountain/dnastorage/system/pipeline_dnafile.py", line 51, in open
    raise Exception("store_header was false, trying file right away")
Exception: store_header was false, trying file right away
Traceback (most recent call last):
  File "/gpfs_backup/tuck_data/atan2/framed-with-fountain/dnastorage/system/pipeline_dnafile.py", line 51, in open
    raise Exception("store_header was false, trying file right away")
Exception: store_header was false, trying file right away
Traceback (most recent call last):
  File "/gpfs_backup/tuck_data/atan2/framed-with-fountain/dnastorage/system/pipeline_dnafile.py", line 51, in open
    raise Exception("store_header was false, trying file right away")
Exception: store_header was false, trying file right away
Traceback (most recent call last):
  File "/gpfs_backup/tuck_data/atan2/framed-with-fountain/dnastorage/system/pipeline_dnafile.py", line 51, in open
    raise Exception("store_header was false, trying file right away")
Exception: store_header was false, trying file right away
Traceback (most recent call last):
  File "/gpfs_backup/tuck_data/atan2/framed-with-fountain/dnastorage/system/pipeline_dnafile.py", line 51, in open
    raise Exception("store_header was false, trying file right away")
Exception: store_header was false, trying file right away
Traceback (most recent call last):
  File "/gpfs_backup/tuck_data/atan2/framed-with-fountain/dnastorage/system/pipeline_dnafile.py", line 51, in open
    raise Exception("store_header was false, trying file right away")
Exception: store_header was false, trying file right away
Traceback (most recent call last):
  File "/gpfs_backup/tuck_data/atan2/framed-with-fountain/dnastorage/system/pipeline_dnafile.py", line 51, in open
    raise Exception("store_header was false, trying file right away")
Exception: store_header was false, trying file right away
Traceback (most recent call last):
  File "/gpfs_backup/tuck_data/atan2/framed-with-fountain/dnastorage/system/pipeline_dnafile.py", line 51, in open
    raise Exception("store_header was false, trying file right away")
Exception: store_header was false, trying file right away
Traceback (most recent call last):
  File "/gpfs_backup/tuck_data/atan2/framed-with-fountain/dnastorage/system/pipeline_dnafile.py", line 51, in open
    raise Exception("store_header was false, trying file right away")
Exception: store_header was false, trying file right away
Traceback (most recent call last):
  File "/gpfs_backup/tuck_data/atan2/framed-with-fountain/dnastorage/system/pipeline_dnafile.py", line 51, in open
    raise Exception("store_header was false, trying file right away")
Exception: store_header was false, trying file right away
Traceback (most recent call last):
  File "/gpfs_backup/tuck_data/atan2/framed-with-fountain/dnastorage/system/pipeline_dnafile.py", line 51, in open
    raise Exception("store_header was false, trying file right away")
Exception: store_header was false, trying file right away
Traceback (most recent call last):
  File "/gpfs_backup/tuck_data/atan2/framed-with-fountain/dnastorage/system/pipeline_dnafile.py", line 51, in open
    raise Exception("store_header was false, trying file right away")
Exception: store_header was false, trying file right away
Traceback (most recent call last):
  File "/gpfs_backup/tuck_data/atan2/framed-with-fountain/dnastorage/system/pipeline_dnafile.py", line 51, in open
    raise Exception("store_header was false, trying file right away")
Exception: store_header was false, trying file right away
Traceback (most recent call last):
  File "/gpfs_backup/tuck_data/atan2/framed-with-fountain/dnastorage/system/pipeline_dnafile.py", line 51, in open
    raise Exception("store_header was false, trying file right away")
Exception: store_header was false, trying file right away
Traceback (most recent call last):
  File "/gpfs_backup/tuck_data/atan2/framed-with-fountain/dnastorage/system/pipeline_dnafile.py", line 51, in open
    raise Exception("store_header was false, trying file right away")
Exception: store_header was false, trying file right away
Traceback (most recent call last):
  File "/gpfs_backup/tuck_data/atan2/framed-with-fountain/dnastorage/system/pipeline_dnafile.py", line 51, in open
    raise Exception("store_header was false, trying file right away")
Exception: store_header was false, trying file right away
Traceback (most recent call last):
  File "/gpfs_backup/tuck_data/atan2/framed-with-fountain/dnastorage/system/pipeline_dnafile.py", line 51, in open
    raise Exception("store_header was false, trying file right away")
Exception: store_header was false, trying file right away
Traceback (most recent call last):
  File "/gpfs_backup/tuck_data/atan2/framed-with-fountain/dnastorage/system/pipeline_dnafile.py", line 51, in open
    raise Exception("store_header was false, trying file right away")
Exception: store_header was false, trying file right away
Traceback (most recent call last):
  File "/gpfs_backup/tuck_data/atan2/framed-with-fountain/dnastorage/system/pipeline_dnafile.py", line 51, in open
    raise Exception("store_header was false, trying file right away")
Exception: store_header was false, trying file right away
Traceback (most recent call last):
  File "/gpfs_backup/tuck_data/atan2/framed-with-fountain/dnastorage/system/pipeline_dnafile.py", line 51, in open
    raise Exception("store_header was false, trying file right away")
Exception: store_header was false, trying file right away
Traceback (most recent call last):
  File "/gpfs_backup/tuck_data/atan2/framed-with-fountain/dnastorage/system/pipeline_dnafile.py", line 51, in open
    raise Exception("store_header was false, trying file right away")
Exception: store_header was false, trying file right away
Traceback (most recent call last):
  File "/gpfs_backup/tuck_data/atan2/framed-with-fountain/dnastorage/system/pipeline_dnafile.py", line 51, in open
    raise Exception("store_header was false, trying file right away")
Exception: store_header was false, trying file right away
Traceback (most recent call last):
  File "/gpfs_backup/tuck_data/atan2/framed-with-fountain/dnastorage/system/pipeline_dnafile.py", line 51, in open
    raise Exception("store_header was false, trying file right away")
Exception: store_header was false, trying file right away
Traceback (most recent call last):
  File "/gpfs_backup/tuck_data/atan2/framed-with-fountain/dnastorage/system/pipeline_dnafile.py", line 51, in open
    raise Exception("store_header was false, trying file right away")
Exception: store_header was false, trying file right away
Traceback (most recent call last):
  File "/gpfs_backup/tuck_data/atan2/framed-with-fountain/dnastorage/system/pipeline_dnafile.py", line 51, in open
    raise Exception("store_header was false, trying file right away")
Exception: store_header was false, trying file right away
Traceback (most recent call last):
  File "/gpfs_backup/tuck_data/atan2/framed-with-fountain/dnastorage/system/pipeline_dnafile.py", line 51, in open
    raise Exception("store_header was false, trying file right away")
Exception: store_header was false, trying file right away
Traceback (most recent call last):
  File "/gpfs_backup/tuck_data/atan2/framed-with-fountain/dnastorage/system/pipeline_dnafile.py", line 51, in open
    raise Exception("store_header was false, trying file right away")
Exception: store_header was false, trying file right away
Traceback (most recent call last):
  File "/gpfs_backup/tuck_data/atan2/framed-with-fountain/dnastorage/system/pipeline_dnafile.py", line 51, in open
    raise Exception("store_header was false, trying file right away")
Exception: store_header was false, trying file right away
Traceback (most recent call last):
  File "/gpfs_backup/tuck_data/atan2/framed-with-fountain/dnastorage/system/pipeline_dnafile.py", line 51, in open
    raise Exception("store_header was false, trying file right away")
Exception: store_header was false, trying file right away
Traceback (most recent call last):
  File "/gpfs_backup/tuck_data/atan2/framed-with-fountain/dnastorage/system/pipeline_dnafile.py", line 51, in open
    raise Exception("store_header was false, trying file right away")
Exception: store_header was false, trying file right away
Traceback (most recent call last):
  File "/gpfs_backup/tuck_data/atan2/framed-with-fountain/dnastorage/system/pipeline_dnafile.py", line 51, in open
    raise Exception("store_header was false, trying file right away")
Exception: store_header was false, trying file right away
Traceback (most recent call last):
  File "/gpfs_backup/tuck_data/atan2/framed-with-fountain/dnastorage/system/pipeline_dnafile.py", line 51, in open
    raise Exception("store_header was false, trying file right away")
Exception: store_header was false, trying file right away
Traceback (most recent call last):
  File "/gpfs_backup/tuck_data/atan2/framed-with-fountain/dnastorage/system/pipeline_dnafile.py", line 51, in open
    raise Exception("store_header was false, trying file right away")
Exception: store_header was false, trying file right away
Traceback (most recent call last):
  File "/gpfs_backup/tuck_data/atan2/framed-with-fountain/dnastorage/system/pipeline_dnafile.py", line 51, in open
    raise Exception("store_header was false, trying file right away")
Exception: store_header was false, trying file right away
Traceback (most recent call last):
  File "/gpfs_backup/tuck_data/atan2/framed-with-fountain/dnastorage/system/pipeline_dnafile.py", line 51, in open
    raise Exception("store_header was false, trying file right away")
Exception: store_header was false, trying file right away
Traceback (most recent call last):
  File "/gpfs_backup/tuck_data/atan2/framed-with-fountain/dnastorage/system/pipeline_dnafile.py", line 51, in open
    raise Exception("store_header was false, trying file right away")
Exception: store_header was false, trying file right away
Traceback (most recent call last):
  File "/gpfs_backup/tuck_data/atan2/framed-with-fountain/dnastorage/system/pipeline_dnafile.py", line 51, in open
    raise Exception("store_header was false, trying file right away")
Exception: store_header was false, trying file right away
Traceback (most recent call last):
  File "/gpfs_backup/tuck_data/atan2/framed-with-fountain/dnastorage/system/pipeline_dnafile.py", line 51, in open
    raise Exception("store_header was false, trying file right away")
Exception: store_header was false, trying file right away
Traceback (most recent call last):
  File "/gpfs_backup/tuck_data/atan2/framed-with-fountain/dnastorage/system/pipeline_dnafile.py", line 51, in open
    raise Exception("store_header was false, trying file right away")
Exception: store_header was false, trying file right away
Traceback (most recent call last):
  File "/gpfs_backup/tuck_data/atan2/framed-with-fountain/dnastorage/system/pipeline_dnafile.py", line 51, in open
    raise Exception("store_header was false, trying file right away")
Exception: store_header was false, trying file right away
Traceback (most recent call last):
  File "/gpfs_backup/tuck_data/atan2/framed-with-fountain/dnastorage/system/pipeline_dnafile.py", line 51, in open
    raise Exception("store_header was false, trying file right away")
Exception: store_header was false, trying file right away
Traceback (most recent call last):
  File "/gpfs_backup/tuck_data/atan2/framed-with-fountain/dnastorage/system/pipeline_dnafile.py", line 51, in open
    raise Exception("store_header was false, trying file right away")
Exception: store_header was false, trying file right away
Traceback (most recent call last):
  File "/gpfs_backup/tuck_data/atan2/framed-with-fountain/dnastorage/system/pipeline_dnafile.py", line 51, in open
    raise Exception("store_header was false, trying file right away")
Exception: store_header was false, trying file right away
Traceback (most recent call last):
  File "/gpfs_backup/tuck_data/atan2/framed-with-fountain/dnastorage/system/pipeline_dnafile.py", line 51, in open
    raise Exception("store_header was false, trying file right away")
Exception: store_header was false, trying file right away
Traceback (most recent call last):
  File "/gpfs_backup/tuck_data/atan2/framed-with-fountain/dnastorage/system/pipeline_dnafile.py", line 51, in open
    raise Exception("store_header was false, trying file right away")
Exception: store_header was false, trying file right away
Traceback (most recent call last):
  File "/gpfs_backup/tuck_data/atan2/framed-with-fountain/dnastorage/system/pipeline_dnafile.py", line 51, in open
    raise Exception("store_header was false, trying file right away")
Exception: store_header was false, trying file right away
Traceback (most recent call last):
  File "/gpfs_backup/tuck_data/atan2/framed-with-fountain/dnastorage/system/pipeline_dnafile.py", line 51, in open
    raise Exception("store_header was false, trying file right away")
Exception: store_header was false, trying file right away
Traceback (most recent call last):
  File "/gpfs_backup/tuck_data/atan2/framed-with-fountain/dnastorage/system/pipeline_dnafile.py", line 51, in open
    raise Exception("store_header was false, trying file right away")
Exception: store_header was false, trying file right away
Traceback (most recent call last):
  File "/gpfs_backup/tuck_data/atan2/framed-with-fountain/dnastorage/system/pipeline_dnafile.py", line 51, in open
    raise Exception("store_header was false, trying file right away")
Exception: store_header was false, trying file right away
Traceback (most recent call last):
  File "/gpfs_backup/tuck_data/atan2/framed-with-fountain/dnastorage/system/pipeline_dnafile.py", line 51, in open
    raise Exception("store_header was false, trying file right away")
Exception: store_header was false, trying file right away
Traceback (most recent call last):
  File "/gpfs_backup/tuck_data/atan2/framed-with-fountain/dnastorage/system/pipeline_dnafile.py", line 51, in open
    raise Exception("store_header was false, trying file right away")
Exception: store_header was false, trying file right away
Traceback (most recent call last):
  File "/gpfs_backup/tuck_data/atan2/framed-with-fountain/dnastorage/system/pipeline_dnafile.py", line 51, in open
    raise Exception("store_header was false, trying file right away")
Exception: store_header was false, trying file right away
Traceback (most recent call last):
  File "/gpfs_backup/tuck_data/atan2/framed-with-fountain/dnastorage/system/pipeline_dnafile.py", line 51, in open
    raise Exception("store_header was false, trying file right away")
Exception: store_header was false, trying file right away
Traceback (most recent call last):
  File "/gpfs_backup/tuck_data/atan2/framed-with-fountain/dnastorage/system/pipeline_dnafile.py", line 51, in open
    raise Exception("store_header was false, trying file right away")
Exception: store_header was false, trying file right away
Traceback (most recent call last):
  File "/gpfs_backup/tuck_data/atan2/framed-with-fountain/dnastorage/system/pipeline_dnafile.py", line 51, in open
    raise Exception("store_header was false, trying file right away")
Exception: store_header was false, trying file right away
Traceback (most recent call last):
  File "/gpfs_backup/tuck_data/atan2/framed-with-fountain/dnastorage/system/pipeline_dnafile.py", line 51, in open
    raise Exception("store_header was false, trying file right away")
Exception: store_header was false, trying file right away
Traceback (most recent call last):
  File "/gpfs_backup/tuck_data/atan2/framed-with-fountain/dnastorage/system/pipeline_dnafile.py", line 51, in open
    raise Exception("store_header was false, trying file right away")
Exception: store_header was false, trying file right away
Traceback (most recent call last):
  File "/gpfs_backup/tuck_data/atan2/framed-with-fountain/dnastorage/system/pipeline_dnafile.py", line 51, in open
    raise Exception("store_header was false, trying file right away")
Exception: store_header was false, trying file right away
Traceback (most recent call last):
  File "/gpfs_backup/tuck_data/atan2/framed-with-fountain/dnastorage/system/pipeline_dnafile.py", line 51, in open
    raise Exception("store_header was false, trying file right away")
Exception: store_header was false, trying file right away
Traceback (most recent call last):
  File "/gpfs_backup/tuck_data/atan2/framed-with-fountain/dnastorage/system/pipeline_dnafile.py", line 51, in open
    raise Exception("store_header was false, trying file right away")
Exception: store_header was false, trying file right away
Traceback (most recent call last):
  File "/gpfs_backup/tuck_data/atan2/framed-with-fountain/dnastorage/system/pipeline_dnafile.py", line 51, in open
    raise Exception("store_header was false, trying file right away")
Exception: store_header was false, trying file right away
Traceback (most recent call last):
  File "/gpfs_backup/tuck_data/atan2/framed-with-fountain/dnastorage/system/pipeline_dnafile.py", line 51, in open
    raise Exception("store_header was false, trying file right away")
Exception: store_header was false, trying file right away
Traceback (most recent call last):
  File "/gpfs_backup/tuck_data/atan2/framed-with-fountain/dnastorage/system/pipeline_dnafile.py", line 51, in open
    raise Exception("store_header was false, trying file right away")
Exception: store_header was false, trying file right away
Traceback (most recent call last):
  File "/gpfs_backup/tuck_data/atan2/framed-with-fountain/dnastorage/system/pipeline_dnafile.py", line 51, in open
    raise Exception("store_header was false, trying file right away")
Exception: store_header was false, trying file right away
Traceback (most recent call last):
  File "/gpfs_backup/tuck_data/atan2/framed-with-fountain/dnastorage/system/pipeline_dnafile.py", line 51, in open
    raise Exception("store_header was false, trying file right away")
Exception: store_header was false, trying file right away
Traceback (most recent call last):
  File "/gpfs_backup/tuck_data/atan2/framed-with-fountain/dnastorage/system/pipeline_dnafile.py", line 51, in open
    raise Exception("store_header was false, trying file right away")
Exception: store_header was false, trying file right away
Traceback (most recent call last):
  File "/gpfs_backup/tuck_data/atan2/framed-with-fountain/dnastorage/system/pipeline_dnafile.py", line 51, in open
    raise Exception("store_header was false, trying file right away")
Exception: store_header was false, trying file right away
Traceback (most recent call last):
  File "/gpfs_backup/tuck_data/atan2/framed-with-fountain/dnastorage/system/pipeline_dnafile.py", line 51, in open
    raise Exception("store_header was false, trying file right away")
Exception: store_header was false, trying file right away
Traceback (most recent call last):
  File "/gpfs_backup/tuck_data/atan2/framed-with-fountain/dnastorage/system/pipeline_dnafile.py", line 51, in open
    raise Exception("store_header was false, trying file right away")
Exception: store_header was false, trying file right away
Traceback (most recent call last):
  File "/gpfs_backup/tuck_data/atan2/framed-with-fountain/dnastorage/system/pipeline_dnafile.py", line 51, in open
    raise Exception("store_header was false, trying file right away")
Exception: store_header was false, trying file right away
Traceback (most recent call last):
  File "/gpfs_backup/tuck_data/atan2/framed-with-fountain/dnastorage/system/pipeline_dnafile.py", line 51, in open
    raise Exception("store_header was false, trying file right away")
Exception: store_header was false, trying file right away
Traceback (most recent call last):
  File "/gpfs_backup/tuck_data/atan2/framed-with-fountain/dnastorage/system/pipeline_dnafile.py", line 51, in open
    raise Exception("store_header was false, trying file right away")
Exception: store_header was false, trying file right away
Traceback (most recent call last):
  File "/gpfs_backup/tuck_data/atan2/framed-with-fountain/dnastorage/system/pipeline_dnafile.py", line 51, in open
    raise Exception("store_header was false, trying file right away")
Exception: store_header was false, trying file right away
Traceback (most recent call last):
  File "/gpfs_backup/tuck_data/atan2/framed-with-fountain/dnastorage/system/pipeline_dnafile.py", line 51, in open
    raise Exception("store_header was false, trying file right away")
Exception: store_header was false, trying file right away
Traceback (most recent call last):
  File "/gpfs_backup/tuck_data/atan2/framed-with-fountain/dnastorage/system/pipeline_dnafile.py", line 51, in open
    raise Exception("store_header was false, trying file right away")
Exception: store_header was false, trying file right away
Traceback (most recent call last):
  File "/gpfs_backup/tuck_data/atan2/framed-with-fountain/dnastorage/system/pipeline_dnafile.py", line 51, in open
    raise Exception("store_header was false, trying file right away")
Exception: store_header was false, trying file right away
Traceback (most recent call last):
  File "/gpfs_backup/tuck_data/atan2/framed-with-fountain/dnastorage/system/pipeline_dnafile.py", line 51, in open
    raise Exception("store_header was false, trying file right away")
Exception: store_header was false, trying file right away
Traceback (most recent call last):
  File "/gpfs_backup/tuck_data/atan2/framed-with-fountain/dnastorage/system/pipeline_dnafile.py", line 51, in open
    raise Exception("store_header was false, trying file right away")
Exception: store_header was false, trying file right away
Traceback (most recent call last):
  File "/gpfs_backup/tuck_data/atan2/framed-with-fountain/dnastorage/system/pipeline_dnafile.py", line 51, in open
    raise Exception("store_header was false, trying file right away")
Exception: store_header was false, trying file right away
Traceback (most recent call last):
  File "/gpfs_backup/tuck_data/atan2/framed-with-fountain/dnastorage/system/pipeline_dnafile.py", line 51, in open
    raise Exception("store_header was false, trying file right away")
Exception: store_header was false, trying file right away
Traceback (most recent call last):
  File "/gpfs_backup/tuck_data/atan2/framed-with-fountain/dnastorage/system/pipeline_dnafile.py", line 51, in open
    raise Exception("store_header was false, trying file right away")
Exception: store_header was false, trying file right away
Traceback (most recent call last):
  File "/gpfs_backup/tuck_data/atan2/framed-with-fountain/dnastorage/system/pipeline_dnafile.py", line 51, in open
    raise Exception("store_header was false, trying file right away")
Exception: store_header was false, trying file right away
Traceback (most recent call last):
  File "/gpfs_backup/tuck_data/atan2/framed-with-fountain/dnastorage/system/pipeline_dnafile.py", line 51, in open
    raise Exception("store_header was false, trying file right away")
Exception: store_header was false, trying file right away
Traceback (most recent call last):
  File "/gpfs_backup/tuck_data/atan2/framed-with-fountain/dnastorage/system/pipeline_dnafile.py", line 51, in open
    raise Exception("store_header was false, trying file right away")
Exception: store_header was false, trying file right away
Traceback (most recent call last):
  File "/gpfs_backup/tuck_data/atan2/framed-with-fountain/dnastorage/system/pipeline_dnafile.py", line 51, in open
    raise Exception("store_header was false, trying file right away")
Exception: store_header was false, trying file right away
Traceback (most recent call last):
  File "/gpfs_backup/tuck_data/atan2/framed-with-fountain/dnastorage/system/pipeline_dnafile.py", line 51, in open
    raise Exception("store_header was false, trying file right away")
Exception: store_header was false, trying file right away
Traceback (most recent call last):
  File "/gpfs_backup/tuck_data/atan2/framed-with-fountain/dnastorage/system/pipeline_dnafile.py", line 51, in open
    raise Exception("store_header was false, trying file right away")
Exception: store_header was false, trying file right away
Traceback (most recent call last):
  File "/gpfs_backup/tuck_data/atan2/framed-with-fountain/dnastorage/system/pipeline_dnafile.py", line 51, in open
    raise Exception("store_header was false, trying file right away")
Exception: store_header was false, trying file right away
Traceback (most recent call last):
  File "/gpfs_backup/tuck_data/atan2/framed-with-fountain/dnastorage/system/pipeline_dnafile.py", line 51, in open
    raise Exception("store_header was false, trying file right away")
Exception: store_header was false, trying file right away
Traceback (most recent call last):
  File "/gpfs_backup/tuck_data/atan2/framed-with-fountain/dnastorage/system/pipeline_dnafile.py", line 51, in open
    raise Exception("store_header was false, trying file right away")
Exception: store_header was false, trying file right away
Traceback (most recent call last):
  File "/gpfs_backup/tuck_data/atan2/framed-with-fountain/dnastorage/system/pipeline_dnafile.py", line 51, in open
    raise Exception("store_header was false, trying file right away")
Exception: store_header was false, trying file right away
Traceback (most recent call last):
  File "/gpfs_backup/tuck_data/atan2/framed-with-fountain/dnastorage/system/pipeline_dnafile.py", line 51, in open
    raise Exception("store_header was false, trying file right away")
Exception: store_header was false, trying file right away
Traceback (most recent call last):
  File "/gpfs_backup/tuck_data/atan2/framed-with-fountain/dnastorage/system/pipeline_dnafile.py", line 51, in open
    raise Exception("store_header was false, trying file right away")
Exception: store_header was false, trying file right away
Traceback (most recent call last):
  File "/gpfs_backup/tuck_data/atan2/framed-with-fountain/dnastorage/system/pipeline_dnafile.py", line 51, in open
    raise Exception("store_header was false, trying file right away")
Exception: store_header was false, trying file right away
Traceback (most recent call last):
  File "/gpfs_backup/tuck_data/atan2/framed-with-fountain/dnastorage/system/pipeline_dnafile.py", line 51, in open
    raise Exception("store_header was false, trying file right away")
Exception: store_header was false, trying file right away
Traceback (most recent call last):
  File "/gpfs_backup/tuck_data/atan2/framed-with-fountain/dnastorage/system/pipeline_dnafile.py", line 51, in open
    raise Exception("store_header was false, trying file right away")
Exception: store_header was false, trying file right away
Traceback (most recent call last):
  File "/gpfs_backup/tuck_data/atan2/framed-with-fountain/dnastorage/system/pipeline_dnafile.py", line 51, in open
    raise Exception("store_header was false, trying file right away")
Exception: store_header was false, trying file right away
Traceback (most recent call last):
  File "/gpfs_backup/tuck_data/atan2/framed-with-fountain/dnastorage/system/pipeline_dnafile.py", line 51, in open
    raise Exception("store_header was false, trying file right away")
Exception: store_header was false, trying file right away
Traceback (most recent call last):
  File "/gpfs_backup/tuck_data/atan2/framed-with-fountain/dnastorage/system/pipeline_dnafile.py", line 51, in open
    raise Exception("store_header was false, trying file right away")
Exception: store_header was false, trying file right away
Traceback (most recent call last):
  File "/gpfs_backup/tuck_data/atan2/framed-with-fountain/dnastorage/system/pipeline_dnafile.py", line 51, in open
    raise Exception("store_header was false, trying file right away")
Exception: store_header was false, trying file right away
Traceback (most recent call last):
  File "/gpfs_backup/tuck_data/atan2/framed-with-fountain/dnastorage/system/pipeline_dnafile.py", line 51, in open
    raise Exception("store_header was false, trying file right away")
Exception: store_header was false, trying file right away
Traceback (most recent call last):
  File "/gpfs_backup/tuck_data/atan2/framed-with-fountain/dnastorage/system/pipeline_dnafile.py", line 51, in open
    raise Exception("store_header was false, trying file right away")
Exception: store_header was false, trying file right away
Traceback (most recent call last):
  File "/gpfs_backup/tuck_data/atan2/framed-with-fountain/dnastorage/system/pipeline_dnafile.py", line 51, in open
    raise Exception("store_header was false, trying file right away")
Exception: store_header was false, trying file right away
Traceback (most recent call last):
  File "/gpfs_backup/tuck_data/atan2/framed-with-fountain/dnastorage/system/pipeline_dnafile.py", line 51, in open
    raise Exception("store_header was false, trying file right away")
Exception: store_header was false, trying file right away
Traceback (most recent call last):
  File "/gpfs_backup/tuck_data/atan2/framed-with-fountain/dnastorage/system/pipeline_dnafile.py", line 51, in open
    raise Exception("store_header was false, trying file right away")
Exception: store_header was false, trying file right away
Traceback (most recent call last):
  File "/gpfs_backup/tuck_data/atan2/framed-with-fountain/dnastorage/system/pipeline_dnafile.py", line 51, in open
    raise Exception("store_header was false, trying file right away")
Exception: store_header was false, trying file right away
Traceback (most recent call last):
  File "/gpfs_backup/tuck_data/atan2/framed-with-fountain/dnastorage/system/pipeline_dnafile.py", line 51, in open
    raise Exception("store_header was false, trying file right away")
Exception: store_header was false, trying file right away
Traceback (most recent call last):
  File "/gpfs_backup/tuck_data/atan2/framed-with-fountain/dnastorage/system/pipeline_dnafile.py", line 51, in open
    raise Exception("store_header was false, trying file right away")
Exception: store_header was false, trying file right away
Traceback (most recent call last):
  File "/gpfs_backup/tuck_data/atan2/framed-with-fountain/dnastorage/system/pipeline_dnafile.py", line 51, in open
    raise Exception("store_header was false, trying file right away")
Exception: store_header was false, trying file right away
Traceback (most recent call last):
  File "/gpfs_backup/tuck_data/atan2/framed-with-fountain/dnastorage/system/pipeline_dnafile.py", line 51, in open
    raise Exception("store_header was false, trying file right away")
Exception: store_header was false, trying file right away
Traceback (most recent call last):
  File "/gpfs_backup/tuck_data/atan2/framed-with-fountain/dnastorage/system/pipeline_dnafile.py", line 51, in open
    raise Exception("store_header was false, trying file right away")
Exception: store_header was false, trying file right away
Traceback (most recent call last):
  File "/gpfs_backup/tuck_data/atan2/framed-with-fountain/dnastorage/system/pipeline_dnafile.py", line 51, in open
    raise Exception("store_header was false, trying file right away")
Exception: store_header was false, trying file right away
Traceback (most recent call last):
  File "/gpfs_backup/tuck_data/atan2/framed-with-fountain/dnastorage/system/pipeline_dnafile.py", line 51, in open
    raise Exception("store_header was false, trying file right away")
Exception: store_header was false, trying file right away
Traceback (most recent call last):
  File "/gpfs_backup/tuck_data/atan2/framed-with-fountain/dnastorage/system/pipeline_dnafile.py", line 51, in open
    raise Exception("store_header was false, trying file right away")
Exception: store_header was false, trying file right away
Traceback (most recent call last):
  File "/gpfs_backup/tuck_data/atan2/framed-with-fountain/dnastorage/system/pipeline_dnafile.py", line 51, in open
    raise Exception("store_header was false, trying file right away")
Exception: store_header was false, trying file right away
Traceback (most recent call last):
  File "/gpfs_backup/tuck_data/atan2/framed-with-fountain/dnastorage/system/pipeline_dnafile.py", line 51, in open
    raise Exception("store_header was false, trying file right away")
Exception: store_header was false, trying file right away
Traceback (most recent call last):
  File "/gpfs_backup/tuck_data/atan2/framed-with-fountain/dnastorage/system/pipeline_dnafile.py", line 51, in open
    raise Exception("store_header was false, trying file right away")
Exception: store_header was false, trying file right away
Traceback (most recent call last):
  File "/gpfs_backup/tuck_data/atan2/framed-with-fountain/dnastorage/system/pipeline_dnafile.py", line 51, in open
    raise Exception("store_header was false, trying file right away")
Exception: store_header was false, trying file right away
Traceback (most recent call last):
  File "/gpfs_backup/tuck_data/atan2/framed-with-fountain/dnastorage/system/pipeline_dnafile.py", line 51, in open
    raise Exception("store_header was false, trying file right away")
Exception: store_header was false, trying file right away
Traceback (most recent call last):
  File "/gpfs_backup/tuck_data/atan2/framed-with-fountain/dnastorage/system/pipeline_dnafile.py", line 51, in open
    raise Exception("store_header was false, trying file right away")
Exception: store_header was false, trying file right away
Traceback (most recent call last):
  File "/gpfs_backup/tuck_data/atan2/framed-with-fountain/dnastorage/system/pipeline_dnafile.py", line 51, in open
    raise Exception("store_header was false, trying file right away")
Exception: store_header was false, trying file right away
Traceback (most recent call last):
  File "/usr/local/usrapps/tuck/atan2/conda/envs/dnastorage/lib/python3.10/site-packages/schwimmbad/mpi.py", line 75, in __init__
    self.wait()
  File "/usr/local/usrapps/tuck/atan2/conda/envs/dnastorage/lib/python3.10/site-packages/schwimmbad/mpi.py", line 141, in wait
    result = func(arg)
  File "/gpfs_backup/tuck_data/atan2/framed-with-fountain/tools/fault_injection.py", line 224, in _monte_parallel_wrapper
    return _monte_kernel(monte_start,monte_end,args,comm=task_comm)
  File "/gpfs_backup/tuck_data/atan2/framed-with-fountain/tools/fault_injection.py", line 172, in _monte_kernel
    bol = decode_file(fountain_to_decode_filename, decoded_fountain_filename, file_blocks_n, fountainless_file_size, systematic_true, encoding_params["packet_size"], encoding_params["rs_size_fountain"])
  File "/gpfs_backup/tuck_data/atan2/framed-with-fountain/dnastorage/lt_codes_python/decode.py", line 50, in decode_file
    recovered_blocks, recovered_n = decode(file_symbols, file_blocks_n, systematic,packet_size, rs_size_fountain)
  File "/gpfs_backup/tuck_data/atan2/framed-with-fountain/dnastorage/lt_codes_python/decoder.py", line 108, in decode
    symbols = recover_graph(symbols, blocks_n, systematic, rs_size_fountain)
  File "/gpfs_backup/tuck_data/atan2/framed-with-fountain/dnastorage/lt_codes_python/decoder.py", line 53, in recover_graph
    neighbors, deg = generate_indexes(symbol.index, symbol.degree, blocks_quantity, systematic)
  File "/gpfs_backup/tuck_data/atan2/framed-with-fountain/dnastorage/lt_codes_python/core.py", line 56, in generate_indexes
    assert degree > 0 and degree <= blocks_quantity, f"degree: {degree}, block quantity: {blocks_quantity}"
AssertionError: degree: 0, block quantity: 87
Abort(0) on node 42 (rank 42 in comm 0): application called MPI_Abort(MPI_COMM_WORLD, 0) - process 42
